Workbook
Name denia: [1]Variables!$B$5
Name festivo: [2]Variables!$C$5
Name lectivo: [2]Variables!$C$3
Name no: [3]Variables!$B$5
Name nolectivo: [2]Variables!$C$4
Name sietehoras: [3]TURNOS!$G$4
Name tram: [1]Variables!$B$3

Sheet FECHA
H2: 1 | I2: Ene | K2: 1 | L2: Enero
B3: DÍA INÍCIO | C3: 45908 | H3: 2 | I3: Feb | K3: 2 | L3: Febrero
H4: 3 | I4: Mar | K4: 3 | L4: Marzo
H5: 4 | I5: Abr | K5: 4 | L5: Abril
H6: 5 | I6: May | K6: 5 | L6: Mayo
H7: 6 | I7: Jun | K7: 6 | L7: Junio
B8: DÍA PUBLICACIÓN | C8: 45905 | H8: 7 | I8: Jul | K8: 7 | L8: Julio
H9: 8 | I9: Ago | K9: 8 | L9: Agosto
H10: 9 | I10: Sep | K10: 9 | L10: Septiembre
H11: 10 | I11: Oct | K11: 10 | L11: Octubre
H12: 11 | I12: Nov | K12: 11 | L12: Noviembre
H13: 12 | I13: Dic | K13: 12 | L13: Diciembre

Sheet TRANVIA
A5: GRÁFICO SERVICIO MAQUINISTAS | D5: =IF(MONTH(D8)=MONTH(J8),"Semana del dia "&DAY(FECHA!$C$3)&" "&"al "&DAY(FECHA!$C$3+6)&" de "&VLOOKUP(MONTH(FECHA!$C$3),FECHA!$H$2:$I$13,2)&" "&YEAR(J8),"Semana del dia "&DAY(FECHA!$C$3)&" "&VLOOKUP(MONTH(FECHA!$C$3),FECHA!$H$2:$I$13,2)&" "&"al "&DAY(FECHA!$C$3+6)&" de "&VLOOKUP(MONTH(J8),FECHA!$H$2:$I$13,2)&" "&YEAR(J8)) -> Semana del dia 8 al 14 de Sep 2025
D7: LUN | E7: MAR | F7: MIE | G7: JUE | H7: VIE | I7: SAB | J7: DOM
A8: CF | C8: NOMBRE DE LOS AGENTES | D8: =DATE(YEAR(FECHA!$C$3),MONTH(FECHA!$C$3),DAY(FECHA!$C$3)) -> 45908 | E8: =D8+1 -> 45909 | F8: =E8+1 -> 45910 | G8: =F8+1 -> 45911 | H8: =G8+1 -> 45912 | I8: =H8+1 -> 45913 | J8: =I8+1 -> 45914
A27: 0 | C27: 0 | D27: 0 | E27: 0 | F27: 0 | G27: 0 | H27: 0 | I27: 0 | J27: 0
A28: 2888 | C28: VILCHES GUTIERREZ, SERGIO | D28: D | E28: D | F28: D | G28: 42 | H28: 35 | I28: 57F | J28: 10F
A29: 0 | C29: 0 | D29: 0 | E29: 0 | F29: 0 | G29: 0 | H29: 0 | I29: 0 | J29: 0
A30: 2432 | C30: DOMENECH GARCIA, JOSE TOMAS | D30: 42 | E30: 49 | F30: D | G30: D | H30: D | I30: 45F | J30: 39F
A31: 0 | C31: 0 | D31: 0 | E31: 0 | F31: 0 | G31: 0 | H31: 0 | I31: 0 | J31: 0
A32: 429 | C32: GRAU GUTIERREZ GUILLERMO | D32: RS | E32: PSIC | F32: RS | G32: RS | H32: D | I32: D | J32: D
A33: 0 | C33: 0 | D33: 0 | E33: 0 | F33: 0 | G33: 0 | H33: 0 | I33: 0 | J33: 0
A34: 605 | C34: MILLAN GRACIA, FRANCISCO JAVIER | D34: D | E34: 41 | F34: 34 | G34: 26 | H34: 13 | I34: 7F | J34: D
A35: 0 | C35: 0 | D35: 0 | E35: 0 | F35: 0 | G35: 0 | H35: 0 | I35: 0 | J35: 0
A36: 2319 | C36: PASTOR LLORENS, CARLOS JOAQUIN | D36: D | E36: D | F36: D | G36: 36 | H36: 57 | I36: 10F | J36: 17F
A37: 0 | C37: 0 | D37: 0 | E37: 0 | F37: 0 | G37: 0 | H37: 0 | I37: 0 | J37: 0
A38: 2283 | C38: GOMIS BRU, MIGUEL ANGEL | D38: 29 | E38: D | F38: D | G38: D | H38: 49 | I38: 35F | J38: 29F
A39: 0 | C39: 0 | D39: 0 | E39: 0 | F39: 0 | G39: 0 | H39: 0 | I39: 0 | J39: 0
A40: 2166 | C40: BARRIL ANTUÑA, LORENZO ANGEL | D40: 21 | E40: 50 | F40: 17 | G40: 19 | H40: D | I40: D | J40: 46F
A41: 0 | C41: 0 | D41: 0 | E41: 0 | F41: 0 | G41: 0 | H41: 0 | I41: 0 | J41: 0
A42: 2696 | C42: GONZALEZ, NAVARRO, RAÚL | D42: D | E42: 57 | F42: 19 | G42: 12 | H42: 8 | I42: D | J42: D
A43: 0 | C43: 0 | D43: 0 | E43: 0 | F43: 0 | G43: 0 | H43: 0 | I43: 0 | J43: 0
A44: 2159 | C44: BLÁZQUEZ ALVAREZ, DAVID | D44: RS | E44: 25 | F44: RS | G44: 59 | H44: RS | I44: 22F | J44: D
D45: 0 | E45: 0 | F45: 0 | G45: 0 | H45: 0 | I45: 0 | J45: 0
D46: 0 | E46: 0 | F46: 0 | G46: 0 | H46: 0 | I46: 0 | J46: 0
D47: 0 | E47: 0 | F47: 0 | G47: 0 | H47: 0 | I47: 0 | J47: 0
D48: 0 | E48: 0 | F48: 0 | G48: 0 | H48: 0 | I48: 0 | J48: 0
A49: 0 | C49: 0 | D49: 0 | E49: 0 | F49: 0 | G49: 0 | H49: 0 | I49: 0 | J49: 0
A50: 2173 | C50: DOMENECH PASTOR, RAFAEL | D50: RS | E50: RS | F50: D | G50: D | H50: D | I50: 55F | J50: 31F
A51: 0 | C51: 0 | D51: 0 | E51: 0 | F51: 0 | G51: 0 | H51: 0 | I51: 0 | J51: 0
A52: 2722 | C52: SIRVENT SEVILLA, PASCUAL | D52: 28 | E52: 37 | F52: 42 | G52: 33 | H52: D | I52: D | J52: D
A53: 0 | C53: 0 | D53: 0 | F53: 0 | G53: 0 | H53: 0 | I53: 0 | J53: 0
A54: 3745 | C54: RODRIGUEZ CREMADES, DAVID | D54: D | E54: 38 | F54: D | G54: 20 | H54: 52 | I54: 3F | J54: D
A55: 0 | C55: 0 | D55: 0 | E55: 0 | F55: 0 | G55: 0 | H55: 0 | I55: 0 | J55: 0
A56: 3178 | C56: SERRANO SANTOS, PABLO | D56: D | E56: D | F56: 49 | G56: 37 | H56: 60 | I56: 36F | J56: 26F
A57: 0 | C57: 0 | D57: 0 | E57: 0 | F57: 0 | G57: 0 | H57: 0 | I57: 0 | J57: 0
A58: 2889 | C58: MARTINEZ PRIETO, ROBERTO CARLOS | D58: 33 | E58: D | F58: D | G58: D | H58: 42 | I58: 27F | J58: 36F
A59: 0 | C59: 0 | D59: 0 | E59: 0 | F59: 0 | G59: 0 | H59: 0 | I59: 0 | J59: 0
A60: 3304 | C60: BERENGUER PEREZ, RAUL | D60: 30 | E60: 21 | F60: 2 | G60: D | H60: 15 | I60: D | J60: 49F
A61: 0 | C61: 0 | D61: 0 | E61: 0 | F61: 0 | G61: 0 | H61: 0 | I61: 0 | J61: 0
A62: 2084 | C62: CABRERA CONDE, DAVID | D62: 41 | E62: RS | F62: RS | G62: 10 | H62: 59 | I62: D | J62: D
A63: 0 | C63: 0 | D63: 0 | E63: 0 | F63: 0 | G63: 0 | H63: 0 | I63: 0 | J63: 0
...

Sheet BOLSA-FORMAC
A5: GRÁFICO AGENTES EN FORMACIÓN | C5: =IF(MONTH(C8)=MONTH(I8),"Semana del dia "&DAY(FECHA!$C$3)&" "&"al "&DAY(FECHA!$C$3+6)&" de "&VLOOKUP(MONTH(FECHA!$C$3),FECHA!$H$2:$I$13,2)&" "&YEAR(I8),"Semana del dia "&DAY(FECHA!$C$3)&" "&VLOOKUP(MONTH(FECHA!$C$3),FECHA!$H$2:$I$13,2)&" "&"al "&DAY(FECHA!$C$3+6)&" de "&VLOOKUP(MONTH(I8),FECHA!$H$2:$I$13,2)&" "&YEAR(I8)) -> Semana del dia 8 al 14 de Sep 2025
C7: LUN | D7: MAR | E7: MIE | F7: JUE | G7: VIE | H7: SAB | I7: DOM
B8: NOMBRE DE LOS AGENTES | C8: =FECHA!$C$3 -> 45908 | D8: =FECHA!$C$3+1 -> 45909 | E8: =FECHA!$C$3+2 -> 45910 | F8: =FECHA!$C$3+3 -> 45911 | G8: =FECHA!$C$3+4 -> 45912 | H8: =FECHA!$C$3+5 -> 45913 | I8: =FECHA!$C$3+6 -> 45914
Q27: =SUM(#REF!) -> #REF!
B28: GARCIA GARCIA, ISMAEL | C28: HAB
B30: GARCIA VIVIENTE, MARCO | C30: HAB
B32: MARTIN SANCHEZ, ALBERTO | C32: HAB
B33: 629 439 426
B34: MONICA NUÑEZ (GESTORA) | C34: M | D34: M | E34: M | F34: M | G34: M | H34: D | I34: D
B35: 618 610 307
B36: M.DOLORES MARTINEZ (GESTORA)
D39: ="El Campello, "& DAY(FECHA!$C$8) & " de " & VLOOKUP(MONTH(FECHA!$C$8),FECHA!$K$2:$L$13,2) & " de " & YEAR(FECHA!$C$8) -> El Campello, 5 de Septiembre de 2025

Sheet USIS ALICANTE
B1: USI TRANVIA ALICANTE
C3: =IF(MONTH(C6)=MONTH(I6),"Semana del dia "&DAY(FECHA!$C$3)&" "&"al "&DAY(FECHA!$C$3+6)&" de "&VLOOKUP(MONTH(FECHA!$C$3),FECHA!$H$2:$I$13,2)&" "&YEAR(I6),"Semana del dia "&DAY(FECHA!$C$3)&" "&VLOOKUP(MONTH(FECHA!$C$3),FECHA!$H$2:$I$13,2)&" "&"al "&DAY(FECHA!$C$3+6)&" de "&VLOOKUP(MONTH(I6),FECHA!$H$2:$I$13,2)&" "&YEAR(I6)) -> Semana del dia 8 al 14 de Sep 2025
C5: LUN | D5: MAR | E5: MIE | F5: JUE | G5: VIE | H5: SAB | I5: DOM
A6: C | B6: NOMBRE DE LOS AGENTES | C6: =DATE(YEAR(FECHA!$C$3),MONTH(FECHA!$C$3),DAY(FECHA!$C$3)) -> 45908 | D6: =C6+1 -> 45909 | E6: =D6+1 -> 45910 | F6: =E6+1 -> 45911 | G6: =F6+1 -> 45912 | H6: =G6+1 -> 45913 | I6: =H6+1 -> 45914
A7: 0 | B7: 0
A8: 2346 | B8: ORTEGA AZUAR, DANIEL | C8: 9 | D8: 10 | E8: 9 | F8: 16 | G8: 12 | H8: 4F | I8: 3F
A9: 0 | B9: 0
A10: 1805 | B10: MARTÍNEZ GARCÍA, LORENA MARIA | C10: 8 | D10: RS | E10: RS | F10: 3 | G10: D | H10: D | I10: D
A11: 0 | B11: 0
A12: 2576 | B12: MONTOYO GARCÍA, GENARO | C12: E | D12: E | E12: E | F12: E | G12: E | H12: D | I12: D
A13: 0 | B13: 0
A14: 1919 | B14: FUENTES GARCIA, MARIA VICTORIA | C14: 5 | D14: 6 | E14: 5 | F14: 5 | G14: 8 | H14: D | I14: D
A15: 0 | B15: 0
A16: 422 | B16: GONZALEZ ZAMORA, FRANCISCO JAVIER | C16: 14 | D16: 7 | E16: 8 | F16: 7 | G16: 5 | H16: D | I16: D
A17: 0 | B17: 0
A18: 557 | B18: MARTIN DE LA RIVA, ANGEL JESUS | C18: D | D18: V | E18: V | F18: V | G18: V | H18: V | I18: 6F
A19: 0 | B19: 0
A20: 2048 | B20: BELTRAN GONZALEZ, NOEMÍ | C20: V | D20: D | E20: D | F20: D | G20: D | H20: V | I20: V
A21: 0 | B21: 0
A22: 2052 | B22: REIG JOVER, PEDRO MIGUEL | C22: 10 | D22: D | E22: D | F22: D | G22: 14 | H22: 13F | I22: 12F
A23: 0 | B23: 0
A24: 2592 | B24: LIMONCHI ROSALES, FRANCISCO J. | C24: 11 | D24: 9 | E24: 10 | F24: 4 | G24: 6 | H24: D | I24: D
A25: 0 | B25: 0
A26: 2328 | B26: GARCIA ABASCAL, MARIA AMALIA | C26: 13 | D26: 11 | E26: 15 | F26: 15 | G26: 10 | H26: 2F | I26: 5F
A27: 0 | B27: 0
A28: 2538 | B28: FERNANDEZ-CAÑADAS JIMENEZ-ORTIZ, EDUARDO | C28: D | D28: D | E28: D | F28: D | G28: 13 | H28: 9F | I28: 10F
A29: 0 | B29: 0
A30: 2562 | B30: CARBONELL ASENSI, MIGUEL ANGEL | C30: D | D30: D | E30: D | F30: D | G30: D | H30: D | I30: D
A31: 0 | B31: 0
A32: 2150 | B32: LÓPEZ VEGARA, ESTEFANÍA | C32: 4 | D32: D | E32: D | F32: D | G32: 15 | H32: 14F | I32: 13F
A33: 0 | B33: 0
A34: 2548 | B34: GOMEZ ACEDO, RAUL | C34: 12 | D34: 8 | E34: 7 | F34: 6 | G34: D | H34: D | I34: D
A35: 0 | B35: 0
A36: 2529 | B36: TENDERO BLANCO, SONIA | C36: E | D36: E | E36: E | F36: E | G36: E | H36: D | I36: D
A37: 0 | B37: 0
A38: 1317 | B38: SALINAS VARO, RAFAEL | C38: V | D38: D | E38: D | F38: D | G38: V | H38: V | I38: V
A39: 0 | B39: 0
A40: 2175 | B40: MARTINEZ ALMAGRO, FRANCISCO RAFAEL | C40: 15 | D40: 13 | E40: 12 | F40: 11 | G40: 2 | H40: D | I40: D
A41: 0 | B41: 0
A42: 2550 | B42: MARTINEZ CLIMENT, MARIA VANESA | C42: D | D42: 12 | E42: 11 | F42: 10 | G42: 9 | H42: 3F | I42: 2F
...

Sheet G_BENIDORM
A1: GRÁFICO DE LA DEPENDENCIA DE BENIDORM
A3: MAQUINISTAS | C3: =IF(MONTH(C6)=MONTH(I6),"Semana del dia "&DAY(FECHA!$C$3)&" "&"al "&DAY(FECHA!$C$3+6)&" de "&VLOOKUP(MONTH(FECHA!$C$3),FECHA!$H$2:$I$13,2)&" "&YEAR(I6),"Semana del dia "&DAY(FECHA!$C$3)&" "&VLOOKUP(MONTH(FECHA!$C$3),FECHA!$H$2:$I$13,2)&" "&"al "&DAY(FECHA!$C$3+6)&" de "&VLOOKUP(MONTH(I6),FECHA!$H$2:$I$13,2)&" "&YEAR(I6)) -> Semana del dia 8 al 14 de Sep 2025
C5: LUN | D5: MAR | E5: MIE | F5: JUE | G5: VIE | H5: SAB | I5: DOM
A6: CF | B6: NOMBRE DE LOS AGENTES | C6: =DATE(YEAR(FECHA!$C$3),MONTH(FECHA!$C$3),DAY(FECHA!$C$3)) -> 45908 | D6: =C6+1 -> 45909 | E6: =D6+1 -> 45910 | F6: =E6+1 -> 45911 | G6: =F6+1 -> 45912 | H6: =G6+1 -> 45913 | I6: =H6+1 -> 45914
A11: 0 | B11: 0 | C11: 0 | D11: 0 | E11: 0 | F11: 0 | G11: 0 | H11: 0 | I11: 0
A12: 109 | B12: BIELSA NOGUES, ERNESTO | C12: PSIC | D12: 6 | E12: D | F12: D | G12: D | H12: V | I12: V
A13: 0 | B13: 0 | C13: 0 | D13: 0 | E13: 0 | F13: 0 | G13: 0 | H13: 0 | I13: 0
A14: 3315 | B14: GARCÍA MARTINEZ, JOSÉ ANTONIO | C14: D | D14: 4 | E14: 4 | F14: D | G14: D | H14: D | I14: D
A15: 0 | B15: 0 | C15: 0 | D15: 0 | E15: 0 | F15: 0 | G15: 0 | H15: 0 | I15: 0
A16: 2154 | B16: LARA NAVARRO, MANUEL | C16: 9 | D16: 5 | E16: 7 | F16: 4 | G16: 9 | H16: D | I16: D
A17: 0 | B17: 0 | C17: 0 | D17: 0 | E17: 0 | F17: 0 | G17: 0 | H17: 0 | I17: 0
A18: 2076 | B18: MENDOZA RODRIGUEZ, JOSÉ ANTONIO | C18: 3 | D18: 8 | E18: 1 | F18: 1 | G18: 8 | H18: D | I18: D
A19: 0 | B19: 0 | C19: 0 | D19: 0 | E19: 0 | F19: 0 | G19: 0 | H19: 0 | I19: 0
A20: 1831 | B20: ALBERT RUIZ, ANTONIO | C20: D | D20: D | E20: 6 | F20: 5 | G20: 7 | H20: 4 | I20: D
A21: 0 | B21: 0 | C21: 0 | D21: 0 | E21: 0 | F21: 0 | G21: 0 | H21: 0 | I21: 0
A22: 2588 | B22: LLOPES MOLINA, JUAN MANUEL | C22: 7 | D22: D | E22: 5 | F22: 7 | G22: 6 | H22: 5 | I22: 9
A23: 0 | B23: 0 | C23: 0 | D23: 0 | E23: 0 | F23: 0 | G23: 0 | H23: 0 | I23: 0
A24: 1651 | B24: PASTOR BERTOMEU, JAIME JUAN | C24: D | D24: D | E24: V | F24: V | G24: D | H24: 7 | I24: 6
A25: 0 | B25: 0 | C25: 0 | D25: 0 | E25: 0 | F25: 0 | G25: 0 | H25: 0 | I25: 0
A26: 2586 | B26: PEREZ SANTAMARIA, MONICA | C26: D | D26: 2 | E26: 3 | F26: 2 | G26: 1 | H26: D | I26: D
A27: 0 | B27: 0 | C27: 0 | D27: 0 | E27: 0 | F27: 0 | G27: 0 | H27: 0 | I27: 0
A28: 3312 | B28: SORIANO DIANA, LORENZO | C28: V | D28: V | E28: V | F28: D | G28: D | H28: D | I28: 4
A29: 0 | B29: 0 | C29: 0 | D29: 0 | E29: 0 | F29: 0 | G29: 0 | H29: 0 | I29: 0
A30: 2575 | B30: LORA OLIVER, ESTHER | C30: E | D30: E | E30: E | F30: D | G30: D | H30: E | I30: E
A31: 0 | B31: 0 | C31: 0 | D31: 0 | E31: 0 | F31: 0 | G31: 0 | H31: 0 | I31: 0
A32: 2094 | B32: HERNANDEZ SANCHEZ, FRANCISCO JAVIER | C32: 5 | D32: 9 | E32: D | F32: 9 | G32: D | H32: 8 | I32: 3 | M32: 1
A33: 0 | B33: 0 | C33: 0 | D33: 0 | E33: 0 | F33: 0 | G33: 0 | H33: 0 | I33: 0 | M33: 2
A34: 3485 | B34: TORREGROSA REDONDO, JORGE | C34: 2 | D34: D | E34: D | F34: 8 | G34: 3 | H34: 2 | I34: 1 | M34: 3
A35: 0 | B35: 0 | C35: 0 | D35: 0 | E35: 0 | F35: 0 | G35: 0 | H35: 0 | I35: 0 | M35: 4
A36: 2800 | B36: BLANES FRACES, DAVID | C36: D | D36: D | E36: D | F36: V | G36: V | H36: V | I36: V | M36: 5
A37: 0 | B37: 0 | C37: 0 | D37: 0 | E37: 0 | F37: 0 | G37: 0 | H37: 0 | I37: 0 | M37: 6
A38: 3743 | B38: SANTOS GARCÍA, PATRICIA | C38: D | D38: 7 | E38: 9 | F38: 6 | G38: 5 | H38: D | I38: D | M38: 7 | Q38: 1
A39: 0 | B39: 0 | C39: 0 | D39: 0 | E39: 0 | F39: 0 | G39: 0 | H39: 0 | I39: 0 | M39: 8 | P39: 1 | Q39: 2
A40: 2210 | B40: MORALES ASENSI, ENRIQUE | C40: 8 | D40: 1 | E40: 2 | F40: D | G40: D | H40: 6 | I40: 7 | M40: 9 | P40: 2 | Q40: 3
A41: 0 | B41: 0 | C41: 0 | D41: 0 | E41: 0 | F41: 0 | G41: 0 | H41: 0 | I41: 0 | M41: 10 | P41: 3 | Q41: 4
A42: 2475 | B42: MORA MAÑEZ, SANTA BEGOÑA | C42: 4 | D42: 3 | E42: 8 | F42: D | G42: D | H42: 9 | I42: 5 | M42: =SUM(M32:M41) -> 55 | P42: 4 | Q42: 5
A43: 0 | B43: 0 | C43: 0 | D43: 0 | E43: 0 | F43: 0 | G43: 0 | H43: 0 | I43: 0 | P43: 5 | Q43: 6
A44: 2316 | B44: ESTEVE GIMENO, ENRIQUETA | C44: 1 | D44: D | E44: D | F44: D | G44: 4 | H44: 3 | I44: 2 | P44: 6 | Q44: 7
A45: 0 | B45: 0 | C45: 0 | D45: 0 | E45: 0 | F45: 0 | G45: 0 | H45: 0 | I45: 0 | P45: 7 | Q45: 8
A46: 409 | B46: GOMEZ SEGURA, JOSE | C46: D | D46: D | E46: D | F46: D | G46: D | H46: D | I46: D | P46: 8 | Q46: 9
...

Sheet USIS BENIDORM
A2: Ferrocarrils de la Generalitat Valenciana
A4: GRÁFICO DE LA DEPENDENCIA DE BENIDORM
A8: GRÁFICO SERVICIO USIS | C8: =IF(MONTH(C11)=MONTH(I11),"Semana del dia "&DAY(FECHA!$C$3)&" "&"al "&DAY(FECHA!$C$3+6)&" de "&VLOOKUP(MONTH(FECHA!$C$3),FECHA!$H$2:$I$13,2)&" "&YEAR(I11),"Semana del dia "&DAY(FECHA!$C$3)&" "&VLOOKUP(MONTH(FECHA!$C$3),FECHA!$H$2:$I$13,2)&" "&"al "&DAY(FECHA!$C$3+6)&" de "&VLOOKUP(MONTH(I11),FECHA!$H$2:$I$13,2)&" "&YEAR(I11)) -> Semana del dia 8 al 14 de Sep 2025
C10: LUN | D10: MAR | E10: MIE | F10: JUE | G10: VIE | H10: SAB | I10: DOM
A11: CF | B11: NOMBRE DE LOS AGENTES | C11: =DATE(YEAR(FECHA!$C$3),MONTH(FECHA!$C$3),DAY(FECHA!$C$3)) -> 45908 | D11: =C11+1 -> 45909 | E11: =D11+1 -> 45910 | F11: =E11+1 -> 45911 | G11: =F11+1 -> 45912 | H11: =G11+1 -> 45913 | I11: =H11+1 -> 45914
A12: 0 | B12: 0
A13: 2561 | B13: GOMEZ BARRERA, JOSE MARIA | C13: D | D13: D | E13: V | F13: V | G13: V | H13: V | I13: V
A14: 0 | B14: 0
A15: 3563 | B15: PERAL LARA, LUIS JAVIER | C15: 1D | D15: 2B | E15: 3D | F15: D | G15: D | H15: 1D | I15: 3A
A16: 0 | B16: 0
A17: 2209 | B17: LLORET ARAGONES, JAUME | C17: V | D17: V | E17: D | F17: D | G17: V | H17: V | I17: V
A18: 0 | B18: 0
A19: 1599 | B19: GINER VERDU, JOSE - ALEXIS | C19: 3D | D19: 3B | E19: 6D | F19: 6C | G19: 6C | H19: D | I19: D
A20: 0 | B20: 0
A21: 1508 | B21: BALTANAS UGARTE, ITZIAR | C21: 5D | D21: D | E21: D | F21: 5C | G21: 5C | H21: 3D | I21: 4A
A22: 0 | B22: 0
A23: 3039 | B23: AGULLO POVEDA, TERESA | C23: D | D23: E | E23: E | F23: E | G23: E | H23: D | I23: D
A24: 0 | B24: 0
A25: 1099 | B25: MURO VENEGAS, JOSE | C25: 2D | D25: 1B | E25: 1D | F25: D | G25: D | H25: 6D | I25: 6A
A26: 0 | B26: 0
A27: 3486 | B27: LOPEZ REIG, NOELIA | C27: D | D27: D | E27: D | F27: D | G27: D | H27: D | I27: D
A28: 0 | B28: 0
A29: 3423 | B29: CHUST LAVAIG, AIDA | C29: D | D29: 6B | E29: 6D | F29: 4C | G29: 2C | H29: D | I29: D
A30: 0 | B30: 0
A31: 3490 | B31: GONZALES CORDOVA, GERALDIN E. | C31: 6D | D31: 4B | E31: 2D | F31: D | G31: D | H31: 5D | I31: 5A
A32: 0 | B32: 0
A33: 3389 | B33: MALAGA BROTONS, LORENA | C33: D | D33: D | E33: D | F33: D | G33: D | H33: 2D | I33: 1A
A34: 0 | B34: 0
A35: 3256 | B35: GARCIA ROMERA, ANA MARIA | C35: D | D35: 3B | E35: 4D | F35: 1C | G35: 4C | H35: D | I35: D
A36: 0 | B36: 0 | C36: 0 | D36: 0 | E36: 0 | F36: 0 | G36: 0 | H36: 0 | I36: 0
A37: 3554 | B37: PONS GIBELI, CATALINA | C37: D | D37: 5B | E37: 5D | F37: 3C | G37: 1C | H37: D | I37: D
C38: 0 | D38: 0 | E38: 0 | F38: 0 | G38: 0 | H38: 0 | I38: 0
A39: 3083 | B39: PEREZ CARRILLO, CRISTINA | C39: 4D | D39: D | E39: 2D | F39: 2C | G39: 3C | H39: 4D | I39: 2A
C40: 0 | D40: 0 | E40: 0 | F40: 0 | G40: 0 | H40: 0 | I40: 0
C42: 0 | D42: 0 | E42: 0 | F42: 0 | G42: 0 | H42: 0 | I42: 0
C43: 0 | D43: 0 | E43: 0 | F43: 0 | G43: 0 | H43: 0 | I43: 0
B44: 618617845 | H44: 0 | I44: 0
A45: 1596 | B45: ORLANDO PEDRÓS SANTOS | C45: M | D45: T | E45: M | F45: M | G45: M | H45: D | I45: D
B46: 619824402 | H46: 0 | I46: 0
A47: 2337 | B47: CRISTINA PARDO RUBIO | C47: V | D47: V | E47: V | F47: V | G47: V | H47: D | I47: D
...

Sheet G_DENIA
A2: Ferrocarrils de la Generalitat Valenciana
A4: GRÁFICO DE LA DEPENDENCIA DE DÉNIA
B7: MAQUINISTAS | C7: =IF(MONTH(C10)=MONTH(I10),"Semana del dia "&DAY(FECHA!$C$3)&" "&"al "&DAY(FECHA!$C$3+6)&" de "&VLOOKUP(MONTH(FECHA!$C$3),FECHA!$H$2:$I$13,2)&" "&YEAR(I10),"Semana del dia "&DAY(FECHA!$C$3)&" "&VLOOKUP(MONTH(FECHA!$C$3),FECHA!$H$2:$I$13,2)&" "&"al "&DAY(FECHA!$C$3+6)&" de "&VLOOKUP(MONTH(I10),FECHA!$H$2:$I$13,2)&" "&YEAR(I10)) -> Semana del dia 8 al 14 de Sep 2025
C9: LUN | D9: MAR | E9: MIE | F9: JUE | G9: VIE | H9: SAB | I9: DOM
A10: CF | B10: NOMBRE DE LOS AGENTES | C10: =DATE(YEAR(FECHA!$C$3),MONTH(FECHA!$C$3),DAY(FECHA!$C$3)) -> 45908 | D10: =C10+1 -> 45909 | E10: =D10+1 -> 45910 | F10: =E10+1 -> 45911 | G10: =F10+1 -> 45912 | H10: =G10+1 -> 45913 | I10: =H10+1 -> 45914
A11: 0 | B11: 0 | C11: 0 | D11: 0 | E11: 0 | F11: 0 | G11: 0 | H11: 0 | I11: 0
A12: 2369 | B12: CABRERA GUERRERO, ENRIQUE | C12: 23 | D12: 25 | E12: 21 | F12: V | G12: V | H12: V | I12: D
A13: 0 | B13: 0 | C13: 0 | D13: 0 | E13: 0 | F13: 0 | G13: 0 | H13: 0 | I13: 0 | O13: 150
A14: 1472 | B14: GOMEZ MARTIN, JAIME | C14: D | D14: D | E14: 23 | F14: 25 | G14: PSIC | H14: 22 | I14: 24
A15: 0 | B15: 0 | C15: 0 | D15: 0 | E15: 0 | F15: 0 | G15: 0 | H15: 0 | I15: 0
A16: 597 | B16: MENA DIAZ, VICTOR | C16: D | D16: D | E16: D | F16: D | G16: D | H16: D | I16: 23
A17: 0 | B17: 0 | C17: 0 | D17: 0 | E17: 0 | F17: 0 | G17: 0 | H17: 0 | I17: 0
A18: 2082 | B18: DE LA TORRE HERRERA, RICARDO | C18: 25 | D18: 21 | E18: 22 | F18: 22 | G18: 24 | H18: 23 | I18: D
A19: 0 | B19: 0 | C19: 0 | D19: 0 | E19: 0 | F19: 0 | G19: 0 | H19: 0 | I19: 0
A20: 2560 | B20: SANJUAN IZQUIERDO, YOLANDA | C20: E | D20: D | E20: D | F20: D | G20: E | H20: E | I20: E
A21: 0 | B21: 0 | C21: 0 | D21: 0 | E21: 0 | F21: 0 | G21: 0 | H21: 0 | I21: 0
A22: 133 | B22: BOU SERRALTA, MIGUEL ANGEL | C22: 22 | D22: 24 | E22: D | F22: D | G22: D | H22: D | I22: V
A23: 0 | B23: 0 | C23: 0 | D23: 0 | E23: 0 | F23: 0 | G23: 0 | H23: 0 | I23: 0
A24: 2049 | B24: COLLADO MASCAROS, IVAN | C24: 21 | D24: D | E24: V | F24: 24 | G24: 21 | H24: 21 | I24: D
A25: 0 | B25: 0 | C25: 0 | D25: 0 | E25: 0 | F25: 0 | G25: 0 | H25: 0 | I25: 0
A26: 159 | B26: CARMONA GARCIA, DIEGO JOSE | C26: D | D26: 23 | E26: 25 | F26: SP2 | G26: 22 | H26: 24 | I26: 21
A27: 0 | B27: 0 | C27: 0 | D27: 0 | E27: 0 | F27: 0 | G27: 0 | H27: 0 | I27: 0
A28: 1204 | B28: DE LAMA GONZALEZ, CARLOS | C28: D | D28: D | E28: D | F28: 23 | G28: 25 | H28: 25 | I28: 22
A29: 0 | B29: 0 | C29: 0 | D29: 0 | E29: 0 | F29: 0 | G29: 0 | H29: 0 | I29: 0
A30: 2805 | B30: FERNANDEZ SANZ, AARON | C30: 24 | D30: LC | E30: D | F30: D | G30: D | H30: D | I30: 25
A31: 0 | B31: 0 | C31: 0 | D31: 0 | E31: 0 | F31: 0 | G31: 0 | H31: 0 | I31: 0
A32: 3027 | B32: SIRERA PASTOR, JOSE JORGE | C32: SP2 | D32: 22 | E32: 24 | F32: 21 | G32: D | H32: D | I32: D
A61: 0 | B61: 650218040
B62: JOSE MANUEL PEREZ FUSTER | C62: T | D62: T | E62: M | F62: M | G62: M | H62: D | I62: D | N62: 51

Sheet USIS DENIA
A3: Ferrocarrils de la Generalitat Valenciana
A5: GRÁFICO DE LA DEPENDENCIA DE DÉNIA
A9: GRÁFICO SERVICIO USIS | C9: =IF(MONTH(C12)=MONTH(I12),"Semana del dia "&DAY(FECHA!$C$3)&" "&"al "&DAY(FECHA!$C$3+6)&" de "&VLOOKUP(MONTH(FECHA!$C$3),FECHA!$H$2:$I$13,2)&" "&YEAR(I12),"Semana del dia "&DAY(FECHA!$C$3)&" "&VLOOKUP(MONTH(FECHA!$C$3),FECHA!$H$2:$I$13,2)&" "&"al "&DAY(FECHA!$C$3+6)&" de "&VLOOKUP(MONTH(I12),FECHA!$H$2:$I$13,2)&" "&YEAR(I12)) -> Semana del dia 8 al 14 de Sep 2025
C11: LUN | D11: MAR | E11: MIE | F11: JUE | G11: VIE | H11: SAB | I11: DOM
A12: CF | B12: NOMBRE DE LOS AGENTES | C12: =DATE(YEAR(FECHA!$C$3),MONTH(FECHA!$C$3),DAY(FECHA!$C$3)) -> 45908 | D12: =C12+1 -> 45909 | E12: =D12+1 -> 45910 | F12: =E12+1 -> 45911 | G12: =F12+1 -> 45912 | H12: =G12+1 -> 45913 | I12: =H12+1 -> 45914
A13: 0 | B13: 0
A14: 1374 | B14: NICOLAU ESCRIVA, LYDIA | C14: D | D14: D | E14: V | F14: V | G14: V | H14: V | I14: V
A15: 0 | B15: 0
A16: 362 | B16: GARCIA MUT, JOSE DANIEL | C16: 4D | D16: D | E16: 1D | F16: 1C | G16: 1C | H16: 1D | I16: 1A
A17: 0 | B17: 0
A18: 3073 | B18: RUIZ BOHAJAR, ROMAN | C18: 1D | D18: 1B | E18: D | F18: D | G18: 4C | H18: 3D | I18: 3A
A19: 0 | B19: 0
A20: 296 | B20: FAR PEREZ, HILARIO VICENTE | C20: D | D20: D | E20: 5D | F20: 5C | G20: 5C | H20: 4D | I20: 4A
A21: 0 | B21: 0
A22: 3550 | B22: CASADO ALCARAZ, FRANCISCO JAVIER | C22: D | D22: 4B | E22: D | F22: D | G22: D | H22: 6D | I22: 6A
A23: 0 | B23: 0
A24: 467 | B24: IBAÑEZ CAPDEVILA, CARLOS | C24: DC | D24: 6B | E24: 3D | F24: 3C | G24: 3C | H24: D | I24: D
A25: 0 | B25: 0
A26: 3355 | B26: SORIANO MUÑOZ, IGNACIO | C26: D | D26: D | E26: V | F26: V | G26: V | H26: V | I26: V
A27: 0 | B27: 0
C28: 0 | D28: 0 | E28: 0 | F28: 0 | G28: 0 | H28: 0 | I28: 0
H29: 0
A30: 3467 | B30: BELTRAN LOPEZ, BORJA | C30: 3D | D30: 3B | E30: 4D | F30: 6C | G30: 6C | H30: D | I30: 5A
A31: 0 | B31: 0 | C31: jui
A32: 3703 | B32: GILABERT HEREDIA, ANGELA MARÍA | C32: D | D32: D | E32: E | F32: E | G32: E | H32: E | I32: E
A33: 0 | B33: 0 | C33: jui
A34: 3487 | B34: CHECA VILLAR, ANDRES | C34: 5D | D34: 5B | E34: D | F34: 2C | G34: D | H34: 2D | I34: 2A
A35: 0 | B35: 0
A36: 3078 | B36: RUIZ ZAMORA, GUSTAVO | C36: E | D36: E | E36: E | F36: E | G36: E | H36: D | I36: D
A37: 0 | B37: 0 | F37: 0
A38: 3731 | B38: DELTELL CORPAS, NAZARET | C38: 2D | D38: 2B | E38: 6D | F38: 4C | G38: 2C | H38: D | I38: D
B39: 618617845 | H39: 0 | I39: 0
A40: 1596 | B40: ORLANDO PEDRÓS SANTOS | C40: M | D40: T | E40: M | F40: M | G40: M | H40: D | I40: D
B41: 619824402 | H41: 0 | I41: 0
A42: 2337 | B42: CRISTINA PARDO RUBIO | C42: V | D42: V | E42: V | F42: V | G42: V | H42: D | I42: D
B43: 689983234 | H43: 0 | I43: 0
A44: 2339 | B44: LAURA SERRANO JOVER | C44: M | D44: M | E44: M | F44: M | G44: M | H44: D | I44: D

Sheet G_REGUL
B2: Ferrocarrils de la Generalitat Valenciana
B4: GRÁFICO DE LA DEPENDENCIA PUESTO MANDO-REGULADORES
D6: =IF(MONTH(D9)=MONTH(J9),"Semana del dia "&DAY(FECHA!$C$3)&" "&"al "&DAY(FECHA!$C$3+6)&" de "&VLOOKUP(MONTH(FECHA!$C$3),FECHA!$H$2:$I$13,2)&" "&YEAR(J9),"Semana del dia "&DAY(FECHA!$C$3)&" "&VLOOKUP(MONTH(FECHA!$C$3),FECHA!$H$2:$I$13,2)&" "&"al "&DAY(FECHA!$C$3+6)&" de "&VLOOKUP(MONTH(J9),FECHA!$H$2:$I$13,2)&" "&YEAR(J9)) -> Semana del dia 8 al 14 de Sep 2025
D8: LUN | E8: MAR | F8: MIE | G8: JUE | H8: VIE | I8: SAB | J8: DOM
B9: C. F. | C9: NOMBRE DE LOS AGENTES | D9: =DATE(YEAR(FECHA!$C$3),MONTH(FECHA!$C$3),DAY(FECHA!$C$3)) -> 45908 | E9: =D9+1 -> 45909 | F9: =E9+1 -> 45910 | G9: =F9+1 -> 45911 | H9: =G9+1 -> 45912 | I9: =H9+1 -> 45913 | J9: =I9+1 -> 45914
B10: 0 | C10: 0 | D10: 0 | E10: 0 | F10: 0 | G10: 0 | H10: 0 | I10: 0 | J10: 0
B11: 2530 | C11: ORTIZ RUBIO, LUIS MANUEL | D11: 8 | E11: 8 | F11: 8 | G11: D | H11: D | I11: D | J11: D
B12: 0 | C12: 0 | D12: 0 | E12: 0 | F12: 0 | G12: 0 | H12: 0 | I12: 0 | J12: 0
B13: 2091 | C13: DÍAZ CASTAÑO, ROBERTO | D13: 7 | E13: 7 | F13: 7 | G13: 8 | H13: D | I13: D | J13: D
B14: 0 | C14: 0 | D14: 0 | E14: 0 | F14: 0 | G14: 0 | H14: 0 | I14: 0 | J14: 0
B15: 2097 | C15: NAVARRO BRAU, NATALIA | D15: 9 | E15: 2 | F15: D | G15: D | H15: 9 | I15: 9 | J15: 9
B16: 0 | C16: 0 | D16: 0 | E16: 0 | F16: 0 | G16: 0 | H16: 0 | I16: 0 | J16: 0
D17: 0 | E17: 0 | F17: 0 | G17: 0 | H17: 0 | I17: 0 | J17: 0
B18: 0 | C18: 0 | D18: 0 | E18: 0 | F18: 0 | G18: 0 | H18: 0 | I18: 0 | J18: 0
B19: 2147 | C19: LÓPEZ SUBIELA, JOAQUÍN | D19: D | E19: 3 | F19: 4 | G19: 5 | H19: 8 | I19: 8 | J19: 8
B20: 0 | C20: 0 | D20: 0 | E20: 0 | F20: 0 | G20: 0 | H20: 0 | I20: 0 | J20: 0
B21: 1499 | C21: SANCHEZ BUENO, BEGOÑA | D21: D | E21: D | F21: D | G21: E | H21: E | I21: E | J21: E
B22: 0 | C22: 0 | D22: 0 | E22: 0 | F22: 0 | G22: 0 | H22: 0 | I22: 0 | J22: 0
B23: 2372 | C23: VILLACIEROS BOIX, CRISTINA | D23: LC | E23: LC | F23: D | G23: D | H23: D | I23: 3 | J23: 1
B24: 0 | C24: 0 | D24: 0 | E24: 0 | F24: 0 | G24: 0 | H24: 0 | I24: 0 | J24: 0
B25: 2004 | C25: CORCOLES GOMEZ, ANTONIO | D25: 5 | E25: 4 | F25: 5 | G25: 6 | H25: D | I25: D | J25: D
B26: 0 | C26: 0 | D26: 0 | E26: 0 | F26: 0 | G26: 0 | H26: 0 | I26: 0 | J26: 0
B27: 2381 | C27: CUEVAS RODRIGUEZ, SILVIA | D27: 1 | E27: D | F27: 1 | G27: 2 | H27: 6 | I27: 4 | J27: 5
B28: 0 | C28: 0 | D28: 0 | E28: 0 | F28: 0 | G28: 0 | H28: 0 | I28: 0 | J28: 0
B29: 2417 | C29: TORMO CABANES, IVAN | D29: 6 | E29: V | F29: D | G29: D | H29: D | I29: V | J29: V
B30: 0 | C30: 0 | D30: 0 | E30: 0 | F30: 0 | G30: 0 | H30: 0 | I30: 0 | J30: 0
B31: 1948 | C31: MONLEON PASCUAL, DAVID MARCO | D31: D | E31: V | F31: V | G31: V | H31: D | I31: D | J31: D
B32: 0 | C32: 0 | D32: 0 | E32: 0 | F32: 0 | G32: 0 | H32: 0 | I32: 0 | J32: 0
B33: 1954 | C33: RODRIGUEZ PECEUX, ANA MARIA | D33: D | E33: D | F33: E | G33: E | H33: E | I33: E | J33: E | P33: 1 | Q33: 1 | R33: 1 | S33: 1 | T33: 1
B34: 0 | C34: 0 | D34: 0 | E34: 0 | F34: 0 | G34: 0 | H34: 0 | I34: 0 | J34: 0 | P34: 2 | Q34: 2 | R34: 2 | S34: 2 | T34: 2
B35: 2215 | C35: GOMEZ CHANA, DAVID | D35: 3 | E35: D | F35: D | G35: D | H35: 1 | I35: 2 | J35: 3 | P35: 3 | Q35: 3 | R35: 3 | S35: 3 | T35: 3
B36: 0 | C36: 0 | D36: 0 | E36: 0 | F36: 0 | G36: 0 | H36: 0 | I36: 0 | J36: 0 | P36: 4 | Q36: 4 | R36: 4 | S36: 4 | T36: 4
B37: 1973 | C37: LLUCH RODRIGUEZ, JOSE | D37: V | E37: 5 | F37: 6 | G37: D | H37: D | I37: D | J37: D | P37: 5 | Q37: 5 | R37: 5 | S37: 5 | T37: 5
B38: 0 | C38: 0 | D38: 0 | E38: 0 | F38: 0 | G38: 0 | H38: 0 | I38: 0 | J38: 0 | P38: 6 | Q38: 6 | R38: 6 | S38: 6 | T38: 6
B39: 2574 | C39: LÓPEZ LÓPEZ, MANUEL | D39: AV | E39: AV | F39: 3 | G39: 4 | H39: 5 | I39: D | J39: D | P39: 7 | Q39: 7 | R39: 7 | S39: 7 | T39: 7
B40: 0 | C40: 0 | D40: 0 | E40: 0 | F40: 0 | G40: 0 | H40: 0 | I40: 0 | J40: 0 | P40: 8 | Q40: 8 | R40: 8 | S40: 8
B41: 1974 | C41: MARTINEZ DUET, MARIA JOSE | D41: D | E41: 1 | F41: 2 | G41: 7 | H41: 7 | I41: 7 | J41: 7 | Q41: 9 | S41: 9
B42: 0 | C42: 0 | D42: 0 | E42: 0 | F42: 0 | G42: 0 | H42: 0 | I42: 0 | J42: 0 | Q42: 10 | R42: 10
B43: 2380 | C43: CARTAGENA MAS, JAVIER | D43: D | E43: D | F43: D | G43: 1 | H43: 2 | I43: 6 | J43: 4 | P43: =SUM(P33:P40) -> 36 | Q43: =SUM(Q33:Q42) -> 55 | R43: =SUM(R33:R42) -> 46 | S43: =SUM(S33:S42) -> 45 | T43: =SUM(T33:T40) -> 28
B44: 0 | C44: 0 | D44: 0 | E44: 0 | F44: 0 | G44: 0 | H44: 0 | I44: 0 | J44: 0
...

Sheet AT.CENTRALIZADA
B2: Ferrocarrils de la Generalitat Valenciana
B4: GRÁFICO DE LA DEPENDENCIA USIS ATENCION CENTRALIZADA
D8: =IF(MONTH(D11)=MONTH(J11),"Semana del dia "&DAY(FECHA!$C$3)&" "&"al "&DAY(FECHA!$C$3+6)&" de "&VLOOKUP(MONTH(FECHA!$C$3),FECHA!$H$2:$I$13,2)&" "&YEAR(J11),"Semana del dia "&DAY(FECHA!$C$3)&" "&VLOOKUP(MONTH(FECHA!$C$3),FECHA!$H$2:$I$13,2)&" "&"al "&DAY(FECHA!$C$3+6)&" de "&VLOOKUP(MONTH(J11),FECHA!$H$2:$I$13,2)&" "&YEAR(J11)) -> Semana del dia 8 al 14 de Sep 2025
D10: LUN | E10: MAR | F10: MIE | G10: JUE | H10: VIE | I10: SAB | J10: DOM
B11: CF | C11: NOMBRE DE LOS AGENTES | D11: =DATE(YEAR(FECHA!$C$3),MONTH(FECHA!$C$3),DAY(FECHA!$C$3)) -> 45908 | E11: =D11+1 -> 45909 | F11: =E11+1 -> 45910 | G11: =F11+1 -> 45911 | H11: =G11+1 -> 45912 | I11: =H11+1 -> 45913 | J11: =I11+1 -> 45914
B13: 3037 | C13: SABATER ALONSO, MARIA ELISA | D13: D | E13: V | F13: V | G13: V | H13: V | I13: D | J13: D
G14: 0
B15: 2810 | C15: LOMAS RODRIGUEZ, GUILLERMO | D15: V | E15: V | F15: V | G15: D | H15: V | I15: V | J15: V
D16: 0 | I16: 0 | J16: 0
B17: 1597 | C17: GALIPIENSO BUFORT, FRANCISCO | D17: D | E17: D | F17: D | G17: D | H17: D | I17: D | J17: D
B19: 1951 | C19: GARCÍA CÁMARA, ANGELES | D19: RS | E19: RS | F19: RS | G19: D | H19: D | I19: 2 | J19: 2
B21: 1972 | C21: CANO CERVERA, ANA ISABEL | D21: 2 | E21: D | F21: D | G21: 3 | H21: 3 | I21: 3 | J21: 3
B23: 2178 | C23: SÁNCHEZ GARCÍA, INMACULADA | D23: D | E23: 2 | F23: 2 | G23: 2 | H23: 1 | I23: D | J23: D
B25: 2245 | C25: GONZALEZ MARTINEZ, LUIS | D25: 3 | E25: 4 | F25: 3 | G25: D | H25: D | I25: 4 | J25: 4
B27: 1959 | C27: CANO CERVERA, MARIA DE LA CRUZ | D27: 4 | E27: D | F27: D | G27: 1 | H27: 2 | I27: 1 | J27: 1
B29: 3074 | C29: ROMERO BONNIER, RAQUEL | D29: D | E29: 3 | F29: 4 | G29: 4 | H29: 4 | I29: D | J29: D
D30: 0 | E30: 0 | F30: 0 | G30: 0 | H30: 0 | I30: 0 | J30: 0
D31: 0 | E31: 0 | F31: 0 | G31: 0 | H31: 0 | I31: 0 | J31: 0
C32: 618617845 | I32: 0 | J32: 0
C33: ORLANDO PEDRÓS SANTOS | D33: M | E33: T | F33: M | G33: M | H33: M | I33: D | J33: D
C34: 619824402 | I34: 0 | J34: 0
C35: CRISTINA PARDO RUBIO | D35: V | E35: V | F35: V | G35: V | H35: V | I35: D | J35: D
C36: 689983234 | I36: 0 | J36: 0
C37: LAURA SERRANO JOVER | D37: M | E37: M | F37: M | G37: M | H37: M | I37: D | J37: D
E39: ="El Campello, "& DAY(FECHA!$C$8) & " de " & VLOOKUP(MONTH(FECHA!$C$8),FECHA!$K$2:$L$13,2) & " de " & YEAR(FECHA!$C$8) -> El Campello, 5 de Septiembre de 2025

Sheet PRACT. ELEC.
B2: Ferrocarrils de la Generalitat Valenciana
B4: GRÁFICO DE PRÁCTICAS MAQUINISTAS ELÉCTRICO
D8: =IF(MONTH(D11)=MONTH(J11),"Semana del dia "&DAY(FECHA!$C$3)&" "&"al "&DAY(FECHA!$C$3+6)&" de "&VLOOKUP(MONTH(FECHA!$C$3),FECHA!$H$2:$I$13,2)&" "&YEAR(J11),"Semana del dia "&DAY(FECHA!$C$3)&" "&VLOOKUP(MONTH(FECHA!$C$3),FECHA!$H$2:$I$13,2)&" "&"al "&DAY(FECHA!$C$3+6)&" de "&VLOOKUP(MONTH(J11),FECHA!$H$2:$I$13,2)&" "&YEAR(J11)) -> Semana del dia 8 al 14 de Sep 2025
D10: LUN | E10: MAR | F10: MIE | G10: JUE | H10: VIE | I10: SAB | J10: DOM
B11: CF | C11: NOMBRE DE LOS AGENTES | D11: =DATE(YEAR(FECHA!$C$3),MONTH(FECHA!$C$3),DAY(FECHA!$C$3)) -> 45908 | E11: =D11+1 -> 45909 | F11: =E11+1 -> 45910 | G11: =F11+1 -> 45911 | H11: =G11+1 -> 45912 | I11: =H11+1 -> 45913 | J11: =I11+1 -> 45914
C36: 650218040
C37: JOSE MANUEL PEREZ FUSTER | D37: M | E37: M | F37: M | G37: M | H37: M | I37: D | J37: D
C38: 660011488
C39: DANIEL HERNANDEZ CHAMBERS | D39: T | E39: T | F39: T | G39: T | H39: T | I39: D | J39: D
E41: ="El Campello, "& DAY(FECHA!$C$8) & " de " & VLOOKUP(MONTH(FECHA!$C$8),FECHA!$K$2:$L$13,2) & " de " & YEAR(FECHA!$C$8) -> El Campello, 5 de Septiembre de 2025

Sheet BOLSA MAQUIS
A5: BENIDORM | C5: =IF(MONTH(C8)=MONTH(I8),"Semana del dia "&DAY(FECHA!$C$3)&" "&"al "&DAY(FECHA!$C$3+6)&" de "&VLOOKUP(MONTH(FECHA!$C$3),FECHA!$H$2:$I$13,2)&" "&YEAR(I8),"Semana del dia "&DAY(FECHA!$C$3)&" "&VLOOKUP(MONTH(FECHA!$C$3),FECHA!$H$2:$I$13,2)&" "&"al "&DAY(FECHA!$C$3+6)&" de "&VLOOKUP(MONTH(I8),FECHA!$H$2:$I$13,2)&" "&YEAR(I8)) -> Semana del dia 8 al 14 de Sep 2025
C7: LUN | D7: MAR | E7: MIE | F7: JUE | G7: VIE | H7: SAB | I7: DOM
A8: CF | B8: NOMBRE DE LOS AGENTES | C8: =FECHA!$C$3 -> 45908 | D8: =FECHA!$C$3+1 -> 45909 | E8: =FECHA!$C$3+2 -> 45910 | F8: =FECHA!$C$3+3 -> 45911 | G8: =FECHA!$C$3+4 -> 45912 | H8: =FECHA!$C$3+5 -> 45913 | I8: =FECHA!$C$3+6 -> 45914
B28: SORIANO DIANA, LORENZO
Q29: 53
B30: TROL CRESPO, JOAQUÍN DAVID | Q30: 54
Q31: 55
B32: GARCÍA MARTÍNEZ,JOSE ANTONIO | Q32: 56
Q33: 57
B34: GONZÁLEZ MUÑOZ, FERNANDO | Q34: 58
Q35: =SUM(Q29:Q34) -> 333
B36: LÓPEZ REDONDO, ALEJANDRO
C43: =SUM(C28:C42) -> 0 | D43: =SUM(D28:D42) -> 0 | E43: =SUM(E28:E42) -> 0 | F43: =SUM(F28:F42) -> 0 | G43: =SUM(G28:G42) -> 0 | H43: =SUM(H28:H42) -> 0 | I43: =SUM(I28:I42) -> 0
B46: MIRAD EN LA SIGUIENTE HOJA EL HORARIO DE LOS TURNOS
B48: HABILITACIONES (EN BENIDORM):
B49: HAB M | C49: 7:30-15:00
B50: HAB T | C50: 14:30-22:00
D73: ="El Campello, "& DAY(FECHA!$C$8) & " de " & VLOOKUP(MONTH(FECHA!$C$8),FECHA!$K$2:$L$13,2) & " de " & YEAR(FECHA!$C$8) -> El Campello, 5 de Septiembre de 2025

Sheet TURNOS PRACTICAS
A4: TURNO | B4: TRENES QUE ACOMPAÑA EL ASPIRANTE, EN CABINA, PARA CONOCIMIENTO DE INFRAESTUCTURA CM-TC-B | C4: INICIO | D4: FIN | E4: JORNADA
A5: 11DP | B5: 1201, 1002 a CM, 1007 de CM, 1010 a CM, 1017 de CM, 1020 a CM, 3029 de CM a TC | C5: 0.22291667 | D5: 0.54861111 | E5: =D5-C5 -> 0.32569444
A6: 12DP | B6: 3012 a CM, 1001 de CM, 1004 a CM, 1009 de CM, 1012 a CM, 1019 de CM, 1022 a CM, 3029 de CM a TC | C6: 0.23263889 | D6: 0.54861111 | E6: =D6-C6 -> 0.31597222
A7: 13DP | B7: 4202 a CM, 1003 de CM, 1006 a CM, 1011 de CM, 1014 a CM, 1021 de CM, 1024 a CM, 3031 de CM a TC | C7: 0.25694444 | D7: 0.56944444 | E7: =D7-C7 -> 0.3125
A8: 14DP | B8: 3052 a CM, 1035 de CM, 1038 a CM, 1043 de CM, 1016 a CM, 1053 de CM, 1056 a CM, Tren-Taxi Especial T-50 (21:10 h) | C8: 0.57777778 | D8: 0.89583333 | E8: =D8-C8 -> 0.31805556
A9: 15DP | B9: 3056 a CM, 1037 de CM, 1040 a CM, 1045 de CM, 1048 a CM, 1055 de CM, 1058 a CM, 3071 de CM a TC | C9: 0.59861111 | D9: 0.92708333 | E9: =D9-C9 -> 0.32847222
A11: LA TOMA Y DEJE DE SERVICIO SE REALIZARÁ EN TALLERES CAMPELLO. SOLICITARÁ AL FACTOR DE CIRCULACIÓN IMPRESO REGISTRO CONOCIMIENTO INFRAESTRUCTURA
A12: ESTE IMPRESO SE ENTREGARÁ CUMPLIMENTADO AL TÉCNICO DE LÍNEA EL DÍA DE LA HABILITACIÓN JUNTO A LAS HOJAS BLANCAS DE LOS BOLETINES DE TRACCIÓN
